Workbook

Sheet Volume por Rota
A1: AGRUPAMENTO | B1: DATA COLETA | C1: COD IMS | D1: COD FORNECEDOR | E1: FORNECEDOR | F1: VEÍCULO | G1: TIPO DE SATURAÇÃO | H1: SATURAÇÃO TOTAL | I1: M³ | J1: PESO | K1: Embalagens | L1: APURAÇÃO MDR | M1: PLANTA
A2: 30951460 | B2: 46168.005 | C2: 24229 | D2: 24229 | E2: CONTINENTAL AUTOMOTI | F2: BIG SIDER | G2: PESO | H2: 43.67 | I2: 73.632 | J2: 10917.9 | K2: 157 | L2: 100 | M2: 1
A3: 30951462 | B3: 46168.006 | C3: 21544 | D3: 21544 | E3: IOCHPE MAXION | F3: BIG SIDER | G3: PESO | H3: 41.3 | I3: 69.755 | J3: 10321 | K3: 36 | L3: 100 | M3: 1
A4: 30951463 | B4: 46168.009 | C4: 18063 | D4: 18063 | E4: AETHRA II CENTAURO | F4: CARRETA | G4: VOLUME | H4: 177.78 | I4: 62.64 | J4: 5898.4 | K4: 16 | L4: 100 | M4: 1
A5: 30951465 | B5: 46168.013 | C5: 10397 | D5: 10397 | E5: AETHRA I | F5: TRUCK | G5: VOLUME | H5: 6.25 | I5: 3.024 | J5: 296 | K5: 1 | L5: 100 | M5: 1
A6: 30951468 | B6: 46168.014 | C6: 46113 | D6: 46113 | E6: NEO STEEL SA | F6: CARRETA | G6: VOLUME | H6: 83.49 | I6: 56.993 | J6: 21526.6 | K6: 155 | L6: 100 | M6: 1
A7: 30951469 | B7: 46168.016 | C7: 1093 | D7: 1093 | E7: MARELLI SISTEMAS AUTOMOTIVOS I | F7: CARRETA | G7: VOLUME | H7: 64.5 | I7: 46.069 | J7: 4354.9 | K7: 608 | L7: 95.2 | M7: 1
A8: 30951470 | B8: 46168.016 | C8: 47060 | D8: 47060 | E8: DENSO IV | F8: CARRETA | G8: VOLUME | H8: 113.33 | I8: 45.11 | J8: 3707.8 | K8: 17 | L8: 100 | M8: 1
A9: 30951471 | B9: 46168.016 | C9: 1097 | D9: 1097 | E9: MAGNETI MARELLI SISTEMAS II | F9: CARRETA REBAIXADA | G9: VOLUME | H9: 64.26 | I9: 50.016 | J9: 9478.9 | K9: 546 | L9: 66.7 | M9: 1
A10: 30951473 | B10: 46168.017 | C10: 21910 | D10: 21910 | E10: INBRASP | F10: TRUCK | G10: VOLUME | H10: 802.38 | I10: 188.371 | J10: 627.1 | K10: 25 | L10: 100 | M10: 1
A11: 30951475 | B11: 46168.021 | C11: 38225 | D11: 38225 | E11: PROMA | F11: BIG SIDER | G11: VOLUME | H11: 103.18 | I11: 88.8 | J11: 7093.3 | K11: 30 | L11: 100 | M11: 1
A12: 30951476 | B12: 46168.022 | C12: 11800 | D12: 11800 | E12: AETHRA II CENTAURO | F12: CARRETA | G12: VOLUME | H12: 171.4 | I12: 83.453 | J12: 7279.4 | K12: 35 | L12: 100 | M12: 1
A13: 30951478 | B13: 46168.024 | C13: 1034 | D13: 1034 | E13: MAGNETI MARELLI SISTEMAS | F13: BIG SIDER | G13: VOLUME | H13: 38.09 | I13: 34.404 | J13: 1727.6 | K13: 32 | L13: 100 | M13: 1
... A163: 30951861 | B163: 46168.385 | C163: 30020 | D163: 30020 | E163: SRK HDB | F163: TRUCK | G163: VOLUME | H163: 121.85 | I163: 54.415 | J163: 5129.7 | K163: 81 | L163: 100 | M163: 1
A164: 30951863 | B164: 46168.386 | C164: 24415 | D164: 800017153 | F164: CARRETA | G164: VOLUME | H164: 0 | I164: 0 | J164: 0 | K164: 0 | L164: 0 | M164: 1
A165: 30951864 | B165: 46168.386 | C165: 38225 | D165: 38225 | E165: PROMA | F165: TRUCK | G165: VOLUME | H165: 161.89 | I165: 46.02 | J165: 6255.9 | K165: 24 | L165: 100 | M165: 1
A166: 30951872 | B166: 46168.39 | C166: 46189 | D166: 46189 | E166: CMP | F166: CARRETA | G166: VOLUME | H166: 220.15 | I166: 80.722 | J166: 1134.2 | K166: 25 | L166: 100 | M166: 1
A167: 30951873 | B167: 46168.391 | C167: 12345 | D167: 12345 | E167: SODECIA MINAS | F167: CARRETA | G167: VOLUME | H167: 200.41 | I167: 92.694 | J167: 9881.3 | K167: 36 | L167: 100 | M167: 1
A168: 30951875 | B168: 46168.392 | C168: 39261 | D168: 39261 | E168: AP BETIM | F168: TRUCK 3M | G168: VOLUME | H168: 88.68 | I168: 36.708 | J168: 4246.8 | K168: 19 | L168: 100 | M168: 1
A169: 30951876 | B169: 46168.392 | C169: 46189 | D169: 46189 | E169: CMP | F169: CARRETA | G169: VOLUME | H169: 118.26 | I169: 84.577 | J169: 5842.5 | K169: 44 | L169: 100 | M169: 1
A170: 30951879 | B170: 46168.393 | C170: 47060 | D170: 47060 | E170: DENSO IV | F170: CARRETA | G170: VOLUME | H170: 80 | I170: 31.842 | J170: 2489.6 | K170: 12 | L170: 100 | M170: 1
A171: 30951880 | B171: 46168.393 | C171: 41469 | D171: 41469 | E171: AISIN | F171: TRUCK | G171: VOLUME | H171: 0 | I171: 0 | J171: 0 | K171: 0 | L171: 0 | M171: 1
A172: 30951881 | B172: 46168.394 | C172: 21910 | D172: 21910 | E172: INBRASP | F172: TRUCK | G172: VOLUME | H172: 602.38 | I172: 141.541 | J172: 458.5 | K172: 19 | L172: 100 | M172: 1
A173: 30951890 | B173: 46168.397 | C173: 20300 | D173: 20300 | E173: BREMBO DO BRASI | F173: TRUCK | G173: PESO | H173: 39.56 | I173: 12.78 | J173: 4746.8 | K173: 9 | L173: 100 | M173: 1
A174: 30951893 | B174: 46168.4 | C174: 21342 | D174: 21342 | E174: VETORE INDUSTRI | F174: TRUCK | G174: PESO | H174: 17.6 | I174: 24.156 | J174: 2112.3 | K174: 745 | L174: 100 | M174: 1
A175: 30951899 | B175: 46168.405 | C175: 33611 | D175: 33611 | E175: TIBERINA | F175: CARRETA | G175: VOLUME | H175: 132.85 | I175: 68.4 | J175: 7537 | K175: 23 | L175: 100 | M175: 1
A176: 30951902 | B176: 46168.407 | C176: 57010 | D176: 57010 | E176: PLASCAR COMPONE | F176: TRUCK | G176: VOLUME | H176: 33.33 | I176: 13.584 | J176: 890.9 | K176: 10 | L176: 100 | M176: 1
... A259: 30952123 | B259: 46168.526 | C259: 15823 | D259: 15823 | E259: WEIDPLAS | F259: CARRETA REBAIXADA | G259: VOLUME | H259: 54.9 | I259: 37.346 | J259: 3060.7 | K259: 39 | L259: 100 | M259: 1
A260: 30952125 | B260: 46168.528 | C260: 1111 | D260: 800020380 | F260: CARRETA | G260: VOLUME | H260: 0 | I260: 33.408 | J260: 5645 | K260: 12 | L260: 0 | M260: 1
A261: 30952126 | B261: 46168.529 | C261: 46892 | D261: 46892 | E261: MARELLI COFAP | F261: CARRETA | G261: VOLUME | H261: 46.75 | I261: 36.588 | J261: 11980.4 | K261: 39 | L261: 100 | M261: 1
A262: 30952128 | B262: 46168.531 | C262: 30408 | D262: 30408 | E262: COSMA DO BRASIL | F262: TRUCK | G262: VOLUME | H262: 9.52 | I262: 4.204 | J262: 1752 | K262: 4 | L262: 80 | M262: 1
A263: 30952129 | B263: 46168.531 | C263: 60643 | D263: 60643 | E263: PLASCAR | F263: TRUCK | G263: VOLUME | H263: 84.34 | I263: 35.736 | J263: 979.6 | K263: 18 | L263: 100 | M263: 1
A264: 30952131 | B264: 46168.533 | C264: 1073 | D264: 1073 | E264: NEMAK ALUMINIO | F264: TRUCK | G264: PESO | H264: 37.29 | I264: 40.8 | J264: 4475.2 | K264: 44 | L264: 100 | M264: 1
A265: 30952133 | B265: 46168.534 | C265: 21910 | D265: 21910 | E265: INBRASP | F265: TRUCK | G265: VOLUME | H265: 602.38 | I265: 141.541 | J265: 453 | K265: 19 | L265: 100 | M265: 1
A266: 30952135 | B266: 46168.534 | C266: 47060 | D266: 47060 | E266: DENSO IV | F266: TRUCK | G266: VOLUME | H266: 56.25 | I266: 24.23 | J266: 2875.6 | K266: 9 | L266: 100 | M266: 1
A267: 30952137 | B267: 46168.535 | C267: 46422 | D267: 46422 | E267: METAL STAMP | F267: CARRETA | G267: VOLUME | H267: 93.65 | I267: 68.16 | J267: 13635.2 | K267: 42 | L267: 83.3 | M267: 1
A268: 30952138 | B268: 46168.535 | C268: 72958 | D268: 72958 | E268: SUMIDENSO | F268: TRUCK | G268: PESO | H268: 6.43 | I268: 3.052 | J268: 770.6 | K268: 48 | L268: 100 | M268: 1
A269: 30952139 | B269: 46168.536 | C269: 76850 | D269: 76850 | E269: USINAS SIDERURGICAS DE MINAS GERAIS | F269: CARRETA | G269: VOLUME | H269: 0 | I269: 0 | J269: 0 | K269: 0 | L269: 0 | M269: 1
A270: 30952143 | B270: 46168.541 | C270: 46189 | D270: 46189 | E270: CMP | F270: CARRETA | G270: VOLUME | H270: 171.65 | I270: 63.734 | J270: 3791.5 | K270: 19 | L270: 100 | M270: 1
A271: 30952144 | B271: 46168.542 | C271: 21544 | D271: 21544 | E271: IOCHPE MAXION | F271: BIG SIDER | G271: PESO | H271: 49.22 | I271: 51.27 | J271: 12307.7 | K271: 42 | L271: 100 | M271: 1
...

Sheet Calculado
A1: AGRUPAMENTO | B1: DATA COLETA | C1: COD IMS | D1: COD FORNECEDOR | E1: FORNECEDOR | F1: VEÍCULO | G1: TIPO DE SATURAÇÃO | H1: SATURAÇÃO TOTAL | I1: M³ | J1: PESO | K1: Embalagens | L1: APURAÇÃO MDR | M1: PLANTA
A2: 30951605 | B2: 46168.216 | C2: 40721 | D2: 40721 | E2: FERROLENE | F2: CARRETA | G2: VOLUME | H2: 0 | I2: 0 | J2: 0 | K2: 0 | L2: 0 | M2: 1
A3: 30951759 | B3: 46168.331 | C3: 30408 | D3: 30408 | E3: COSMA DO BRASIL | F3: TRUCK | G3: VOLUME | H3: 0 | I3: 0 | J3: 0 | K3: 0 | L3: 0 | M3: 1
A4: 30951847 | B4: 46168.379 | C4: 40721 | D4: 40721 | E4: FERROLENE | F4: CARRETA | G4: VOLUME | H4: 0 | I4: 0 | J4: 0 | K4: 0 | L4: 0 | M4: 1
A5: 30951863 | B5: 46168.386 | C5: 24415 | D5: 800017153 | F5: CARRETA | G5: VOLUME | H5: 0 | I5: 0 | J5: 0 | K5: 0 | L5: 0 | M5: 1
A6: 30951880 | B6: 46168.393 | C6: 41469 | D6: 41469 | E6: AISIN | F6: TRUCK | G6: VOLUME | H6: 0 | I6: 0 | J6: 0 | K6: 0 | L6: 0 | M6: 1
A7: 30951930 | B7: 46168.419 | C7: 20169 | D7: 20169 | E7: BRIDGESTONE | F7: CARRETA | G7: VOLUME | H7: 0 | I7: 71.131 | J7: 156126 | K7: 42 | L7: 0 | M7: 1
A8: 30951936 | B8: 46168.421 | C8: 40721 | D8: 40721 | E8: FERROLENE | F8: CARRETA | G8: VOLUME | H8: 0 | I8: 0 | J8: 0 | K8: 0 | L8: 0 | M8: 1
A9: 30951983 | B9: 46168.445 | C9: 20173 | D9: 20173 | E9: CONTINENTAL | F9: CARRETA | G9: VOLUME | H9: 0 | I9: 74.518 | J9: 164009 | K9: 44 | L9: 0 | M9: 1
A10: 30952041 | B10: 46168.477 | C10: 40721 | D10: 40721 | E10: FERROLENE | F10: CARRETA | G10: VOLUME | H10: 0 | I10: 0 | J10: 0 | K10: 0 | L10: 0 | M10: 1
A11: 30952125 | B11: 46168.528 | C11: 1111 | D11: 800020380 | F11: CARRETA | G11: VOLUME | H11: 0 | I11: 33.408 | J11: 5645 | K11: 12 | L11: 0 | M11: 1
A12: 30952139 | B12: 46168.536 | C12: 76850 | D12: 76850 | E12: USINAS SIDERURGICAS DE MINAS GERAIS | F12: CARRETA | G12: VOLUME | H12: 0 | I12: 0 | J12: 0 | K12: 0 | L12: 0 | M12: 1
A13: 30952208 | B13: 46168.585 | C13: 40721 | D13: 40721 | E13: FERROLENE | F13: CARRETA | G13: VOLUME | H13: 0 | I13: 38.671 | J13: 4350 | K13: 15 | L13: 0 | M13: 1
A14: 30952229 | B14: 46168.593 | C14: 23693 | D14: 23693 | E14: USIMINAS | F14: CARRETA | G14: VOLUME | H14: 0 | I14: 0 | J14: 0 | K14: 0 | L14: 0 | M14: 1
A15: 30952254 | B15: 46168.603 | C15: 76850 | D15: 76850 | E15: USINAS SIDERURGICAS DE MINAS GERAIS | F15: CARRETA | G15: VOLUME | H15: 0 | I15: 0 | J15: 0 | K15: 0 | L15: 0 | M15: 1
A16: 30952261 | B16: 46168.61 | C16: 1093 | D16: 1093 | E16: MARELLI SISTEMAS AUTOMOTIVOS I | F16: CARRETA | G16: VOLUME | H16: 0 | I16: 2.34 | J16: 524.7 | K16: 2 | L16: 0 | M16: 1
A17: 30952334 | B17: 46168.648 | C17: 12896 | D17: 12896 | E17: NEO POLIMEROS LTDA | F17: CARRETA | G17: VOLUME | H17: 0 | I17: 0 | J17: 0 | K17: 0 | L17: 0 | M17: 1
A18: 30952392 | B18: 46168.679 | C18: 40721 | D18: 40721 | E18: FERROLENE | F18: CARRETA | G18: VOLUME | H18: 0 | I18: 0 | J18: 0 | K18: 0 | L18: 0 | M18: 1
A19: 30952492 | B19: 46168.738 | C19: 40721 | D19: 40721 | E19: FERROLENE | F19: CARRETA | G19: VOLUME | H19: 0 | I19: 0 | J19: 0 | K19: 0 | L19: 0 | M19: 1
A20: 30952604 | B20: 46168.805 | C20: 1093 | D20: 1093 | E20: MARELLI SISTEMAS AUTOMOTIVOS I | F20: CARRETA | G20: VOLUME | H20: 0 | I20: 2.34 | J20: 524.7 | K20: 2 | L20: 0 | M20: 1
A21: 30952645 | B21: 46168.829 | C21: 30408 | D21: 30408 | E21: COSMA DO BRASIL | F21: TRUCK | G21: VOLUME | H21: 0 | I21: 0 | J21: 0 | K21: 0 | L21: 0 | M21: 1
A22: 30952697 | B22: 46168.872 | C22: 40721 | D22: 40721 | E22: FERROLENE | F22: CARRETA | G22: VOLUME | H22: 0 | I22: 0 | J22: 0 | K22: 0 | L22: 0 | M22: 1
A23: 30952759 | B23: 46168.918 | C23: 1128 | D23: 1128 | E23: FIAT AUTOMOVEIS | F23: CARRETA | G23: VOLUME | H23: 0 | I23: 0 | J23: 0 | K23: 0 | L23: 0 | M23: 1
... A103: 30957973 | B103: 46173.764 | C103: 51620 | D103: 51620 | E103: MAHLE PISTOES | F103: TRUCK | G103: VOLUME | H103: 0 | I103: 4.824 | J103: 1844.2 | K103: 402 | L103: 0 | M103: 1

Sheet Old
A1: =_xlfn.XLOOKUP(B1,Calculado!A:A,Calculado!I:I) -> 4.824 | B1: 30957973 | C1: 46173.764 | D1: 0 | E1: TRUCK | F1: VOLUME | G1: 0 | H1: 4.824 | I1: #Valor! | J1: 1844.191 | K1: 402 | L1: 191679.05 | M1: 0.5 | N1: - | O1: FALSE | P1: #Valor! | Q1: 0 | R1: 8 x 2,4 x 2,8 | S1: 53.76 | T1: 12000
A2: =_xlfn.XLOOKUP(B2,Calculado!A:A,Calculado!I:I) -> #N/A | B2: 30957966 | C2: 46173.707 | D2: 0 | E2: CARRETA | F2: VOLUME | G2: 0 | H2: 29.0774 | I2: #Valor! | J2: 6909 | K2: 16 | L2: 0 | M2: 0.5 | N2: - | O2: FALSE | P2: #Valor! | Q2: 0 | R2: 14 x 2,4 x 2,78 | S2: 94.08 | T2: 25000
A3: =_xlfn.XLOOKUP(B3,Calculado!A:A,Calculado!I:I) -> #N/A | B3: 30957959 | C3: 46173.581 | D3: 0 | E3: CARRETA | F3: VOLUME | G3: 0 | H3: 0 | I3: 0 | J3: 0 | K3: 0 | L3: 0 | M3: 0 | N3: - | O3: FALSE | P3: 0 | Q3: 0 | R3: 14 x 2,4 x 2,78 | S3: 94.08 | T3: 25000
A4: =_xlfn.XLOOKUP(B4,Calculado!A:A,Calculado!I:I) -> #N/A | B4: 30957756 | C4: 46172.742 | D4: 0 | E4: VANDERLEA | F4: VOLUME | G4: 0 | H4: 9.2568 | I4: #Valor! | J4: 3640 | K4: 7 | L4: 0 | M4: 0.5 | N4: - | O4: FALSE | P4: #Valor! | Q4: 0 | R4: 14 x 2,4 x 2,78 | S4: 94.08 | T4: 34000
A5: =_xlfn.XLOOKUP(B5,Calculado!A:A,Calculado!I:I) -> #N/A | B5: 30957740 | C5: 46172.729 | D5: 0 | E5: CARRETA | F5: VOLUME | G5: 0 | H5: 0 | I5: 0 | J5: 0 | K5: 0 | L5: 0 | M5: 0 | N5: - | O5: FALSE | P5: 0 | Q5: 0 | R5: 14 x 2,4 x 2,78 | S5: 94.08 | T5: 25000
A6: =_xlfn.XLOOKUP(B6,Calculado!A:A,Calculado!I:I) -> #N/A | B6: 30957705 | C6: 46172.699 | D6: 0 | E6: BIG SIDER | F6: VOLUME | G6: 0 | H6: 0 | I6: #Valor! | J6: 0 | K6: 0 | L6: 0 | M6: 0 | N6: - | O6: FALSE | P6: #Valor! | Q6: 0 | R6: 15 x 2,4 x 3 | S6: 108 | T6: 25000
A7: =_xlfn.XLOOKUP(B7,Calculado!A:A,Calculado!I:I) -> #N/A | B7: 30957592 | C7: 46172.591 | D7: 0 | E7: CARRETA | F7: Peso | G7: 0 | H7: 67.681195 | I7: #Valor! | J7: 18959.264 | K7: 37 | L7: 0 | M7: 0.5 | N7: - | O7: FALSE | P7: #Valor! | Q7: 0 | R7: 14 x 2,4 x 2,78 | S7: 94.08 | T7: 25000
A8: =_xlfn.XLOOKUP(B8,Calculado!A:A,Calculado!I:I) -> 0 | B8: 30957578 | C8: 46172.575 | D8: 0 | E8: CARRETA | F8: VOLUME | G8: 0 | H8: 0 | I8: #Valor! | J8: 0 | K8: 0 | L8: 0 | M8: 0 | N8: - | O8: FALSE | P8: #Valor! | Q8: 0 | R8: 14 x 2,4 x 2,78 | S8: 94.08 | T8: 25000
A9: =_xlfn.XLOOKUP(B9,Calculado!A:A,Calculado!I:I) -> 0 | B9: 30957571 | C9: 46172.569 | D9: 0 | E9: CARRETA | F9: VOLUME | G9: 0 | H9: 0 | I9: #Valor! | J9: 0 | K9: 0 | L9: 0 | M9: 0 | N9: - | O9: FALSE | P9: #Valor! | Q9: 0 | R9: 14 x 2,4 x 2,78 | S9: 94.08 | T9: 25000
A10: =_xlfn.XLOOKUP(B10,Calculado!A:A,Calculado!I:I) -> 0 | B10: 30957553 | C10: 46172.55 | D10: 0 | E10: CARRETA | F10: VOLUME | G10: 0 | H10: 0 | I10: #Valor! | J10: 0 | K10: 0 | L10: 0 | M10: 0 | N10: - | O10: FALSE | P10: #Valor! | Q10: 0 | R10: 14 x 2,4 x 2,78 | S10: 94.08 | T10: 25000
A11: =_xlfn.XLOOKUP(B11,Calculado!A:A,Calculado!I:I) -> #N/A | B11: 30957469 | C11: 46172.466 | D11: 0 | E11: VANDERLEA | F11: VOLUME | G11: 0 | H11: 9.2568 | I11: #Valor! | J11: 3640 | K11: 7 | L11: 0 | M11: 0.5 | N11: - | O11: FALSE | P11: #Valor! | Q11: 0 | R11: 14 x 2,4 x 2,78 | S11: 94.08 | T11: 34000
A12: =_xlfn.XLOOKUP(B12,Calculado!A:A,Calculado!I:I) -> 0 | B12: 30957456 | C12: 46172.458 | D12: 0 | E12: TRUCK | F12: VOLUME | G12: 0 | H12: 0 | I12: #Valor! | J12: 0 | K12: 0 | L12: 0 | M12: 0 | N12: - | O12: FALSE | P12: #Valor! | Q12: 0 | R12: 8 x 2,4 x 2,8 | S12: 53.76 | T12: 12000
A13: =_xlfn.XLOOKUP(B13,Calculado!A:A,Calculado!I:I) -> #N/A | B13: 30957427 | C13: 46172.433 | D13: 0 | E13: TRUCK | F13: VOLUME | G13: 0 | H13: 21.858036 | I13: #Valor! | J13: 9111.456 | K13: 126 | L13: 0 | M13: 0.5 | N13: - | O13: FALSE | P13: #Valor! | Q13: 0 | R13: 8 x 2,4 x 2,8 | S13: 53.76 | T13: 12000
A14: =_xlfn.XLOOKUP(B14,Calculado!A:A,Calculado!I:I) -> 139.612 | B14: 30957424 | C14: 46172.428 | D14: 0 | E14: CARRETA | F14: VOLUME | G14: 0 | H14: 139.6125 | I14: #Valor! | J14: 27000 | K14: 25 | L14: 0 | M14: 0.5 | N14: - | O14: FALSE | P14: #Valor! | Q14: 0 | R14: 14 x 2,4 x 2,78 | S14: 94.08 | T14: 25000
A15: =_xlfn.XLOOKUP(B15,Calculado!A:A,Calculado!I:I) -> 0 | B15: 30957393 | C15: 46172.395 | D15: 0 | E15: CARRETA | F15: VOLUME | G15: 0 | H15: 0 | I15: #Valor! | J15: 0 | K15: 0 | L15: 0 | M15: 0 | N15: - | O15: FALSE | P15: #Valor! | Q15: 0 | R15: 14 x 2,4 x 2,78 | S15: 94.08 | T15: 25000
A16: =_xlfn.XLOOKUP(B16,Calculado!A:A,Calculado!I:I) -> 0 | B16: 30957318 | C16: 46172.338 | D16: 0 | E16: TRUCK | F16: VOLUME | G16: 0 | H16: 0 | I16: #Valor! | J16: 0 | K16: 0 | L16: 0 | M16: 0 | N16: - | O16: FALSE | P16: #Valor! | Q16: 0 | R16: 8 x 2,4 x 2,8 | S16: 53.76 | T16: 12000
A17: =_xlfn.XLOOKUP(B17,Calculado!A:A,Calculado!I:I) -> 79.599 | B17: 30957227 | C17: 46172.255 | D17: 0 | E17: CARRETA | F17: VOLUME | G17: 0 | H17: 79.5992 | I17: #Valor! | J17: 174459.5 | K17: 47 | L17: 0 | M17: 0.5 | N17: - | O17: FALSE | P17: #Valor! | Q17: 0 | R17: 14 x 2,4 x 2,78 | S17: 94.08 | T17: 25000
... A198: =_xlfn.XLOOKUP(B198,Calculado!A:A,Calculado!I:I) -> #N/A | B198: 30951538 | C198: 46168.096 | D198: 0 | E198: CARRETA | F198: VOLUME | G198: 0 | H198: 0 | I198: #Valor! | J198: 0 | K198: 0 | L198: 0 | M198: 0 | N198: - | O198: FALSE | P198: #Valor! | Q198: 0 | R198: 14 x 2,4 x 2,78 | S198: 94.08 | T198: 25000
